Workbook
Name HubMemberIDs: 'Lookups'!$A$2:$A$27
Name HubMemberNames: 'Lookups'!$B$2:$B$27
Name HubMemberEmails: 'Lookups'!$C$2:$C$27
Name HubStates: 'Lookups'!$D$2:$D$4
Name HubBooleans: 'Lookups'!$E$2:$E$3
Name HubRoles: 'Lookups'!$F$2:$F$4
Name HubEventTypes: 'Lookups'!$G$2:$G$5
Name HubTaskStatuses: 'Lookups'!$H$2:$H$6
Name HubCategories: 'Lookups'!$I$2:$I$6
Name HubSkillNames: 'Lookups'!$J$2:$J$28
Name HubEventKeys: 'Lookups'!$K$2:$K$62
Name HubAdminEmails: 'Lookups'!$M$2:$M$2
Name HubProjectCategories: 'Lookups'!$I$2:$I$4
Name HubSubteamIDs: 'Lookups'!$N$2:$N$4
Name HubMembershipRoles: 'Lookups'!$P$2:$P$4
Name HubTeamColors: 'Lookups'!$Q$2:$Q$6

Sheet Workbook Guide
A1: ASAR TEAM HUB | B1: Workbook & review workflow
A2: START HERE | B2: This workbook matches the shared frontend and Apps Script backend. Source cells are preserved; the inactive Exam sheet is hidden.
A3: Essential event fields | B3: Tasks use title, description, assignees, status and due date. Meetings use title, date, participants, link/location and attendance logging. Courses use title, course link and assigned members, with optional track, requirement and deadline settings.
A4: Task workflow | B4: Update task status using the Kanban drag-and-drop board or the status dropdown. There is no task completion form. Completed status counts for all assignees; moving back to an open status reverses that progress.
A5: Course workflow | B5: Uncompleted > Pending > Completed. Evidence is optional. Members can submit without a file, or attach a PDF, PNG or JPEG up to 10 MB. Only an admin approval counts toward progress.
A6: Background saves | B6: New events appear as saving drafts immediately while the app stays usable. A compact indicator beside Refresh shows pending changes and opens failure details for retry. Unconfirmed drafts do not count in progress. Retries reuse the same event ID to prevent duplicates.
A7: Event deletion | B7: Only enabled admins can delete tasks, meetings and courses. Deleted TRUE on the source event and linked Log rows removes the event from assignments, progress and review queues. Completion attempts, evidence and Activity remain recorded. Queued announcements are cancelled. Use the app for consistent deletion; do not remove or reorder historical rows.
A8: References | B8: Every active member can add a title, http/https URL and optional description in References. Only enabled admins can delete links. Added By, Added By Name, Added At and Deleted are app-managed fields; deletion preserves the source row and Activity history.
A9: Task evidence | B9: Task assignees and admins add completion or issue links directly on the task card. Evidence Links is an app-managed field on Task that retains author, time, purpose, note and removed-link history. Adding a link never changes board status.
A10: Activity review | B10: Activity includes user submissions, approvals, task evidence, settings changes and authenticated request failures. Use member/category/search filters and open details to investigate errors or request IDs. Completion retains the individual review records.
A11: Meeting workflow | B11: An admin opens Logging Enabled. Members submit attendance for review; evidence is optional. Only approved attendance counts toward progress.
A12: Undo and update | B12: Members can withdraw Pending or undo Completed records from their event card, including imported completions. Status returns to Uncompleted. Resubmission creates a new attempt and requires review again.
... A31: Maintenance | B31: Run python tools/style_workbook.py after changing the source schema or roster to refresh lookups and the delivery workbook. This also rebuilds CSVs and both app interfaces.

Sheet Supervisor
A1: Name | B1: phone
A2: Dr Bassant | B2: 17352734
A5: https://youtu.be/E2olFc-th7A?si=hVvhglltlywirFsF
A6: https://teracourses.com/ar/course/c-plus-plus-course6?utm_source=chatgpt.com
A7: https://teracourses.com/ar/course/c-plus-plus-course20?utm_source=chatgpt.com
A8: https://www.youtube.com/watch?v=owCqVRbZlbg&utm_source=chatgpt.com
A9: https://www.youtube.com/results?search_query=Algorithms+%D8%A8%D8%A7%D9%84%D8%B9%D8%B1%D8%A8%D9%8A+Data+Structures+Algorithms&utm_source=chatgpt.com
A10: https://teracourses.com/ar/course/c-plus-plus-course6?utm_source=chatgpt.com
A11: https://elzero.org/category/courses/git-and-github/?utm_source=chatgpt.com
A12: https://www.youtube.com/results?search_query=Linux+Command+Line+%D8%A8%D8%A7%D9%84%D8%B9%D8%B1%D8%A8%D9%8A+%D9%83%D9%88%D8%B1%D8%B3&utm_source=chatgpt.com
A13: https://www.youtube.com/results?search_query=Clean+Code+%D8%A8%D8%A7%D9%84%D8%B9%D8%B1%D8%A8%D9%8A+%D9%83%D9%88%D8%B1%D8%B3&utm_source=chatgpt.com
A14: https://www.youtube.com/results?search_query=Software+Engineering+%D8%A8%D8%A7%D9%84%D8%B9%D8%B1%D8%A8%D9%8A+%D9%83%D9%88%D8%B1%D8%B3&utm_source=chatgpt.com
A15: https://www.youtube.com/results?search_query=Computer+Architecture+%D8%A8%D8%A7%D9%84%D8%B9%D8%B1%D8%A8%D9%8A+%D9%83%D9%88%D8%B1%D8%B3&utm_source=chatgpt.com
A16: https://www.youtube.com/results?search_query=Operating+Systems+%D8%A8%D8%A7%D9%84%D8%B9%D8%B1%D8%A8%D9%8A+%D9%83%D9%88%D8%B1%D8%B3&utm_source=chatgpt.com
... A35: https://www.youtube.com/watch?v=gHg8mgppTSQ&utm_source=chatgpt.com
A36: https://t.me/s/EngineeringTutorials?after=142&utm_source=chatgpt.com | C36: https://www.youtube.com/playlist?list=PL6qXLz2O0IoM2zcRXPYXesMq_hcFfQ6OL&utm_source=chatgpt.com
A37: https://teracourses.com/ar/course/solidworks-course4?utm_source=chatgpt.com
A38: https://teracourses.com/ar/course/solidworks-course4?utm_source=chatgpt.com
A39: https://arbcours.blogspot.com/2017/06/Course-Solidworks-training-for-beginner.html?utm_source=chatgpt.com
A40: https://arbcours.blogspot.com/2017/06/Course-Solidworks-training-for-beginner.html?utm_source=chatgpt.com
A41: Mahara-Tech
A42: https://maharatech.gov.eg/course/view.php?id=2247&utm_source=chatgpt.com
A43: https://maharatech.gov.eg/course/view.php?id=2271&lang=ar&utm_source=chatgpt.com
A44: https://stagging.maharatech.gov.eg/course/view.php?id=2206&utm_source=chatgpt.com
A45: https://maharatech.gov.eg/course/view.php?id=32&utm_source=chatgpt.com
A46: https://maharatech.gov.eg/course/view.php?id=14&lang=ar&utm_source=chatgpt.com
A47: https://maharatech.gov.eg/course/view.php?id=2368&lang=en&utm_source=chatgpt.com
A48: https://maharatech.gov.eg/course/index.php?lang=ar&utm_source=chatgpt.com

Sheet Activity
A1: Timestamp | B1: Email | C1: Action | D1: Target | E1: Details
A2: 46277.591 | B2: muhamedrefaat777@gmail.com | C2: createTask | D2: aa | E2: {"assignees":["Abdallah Refaat "]}
A3: 46277.784 | B3: test.user@azar.com | C3: updateTask | D3: aa | E3: {"status":"Backlog","score":""}
A4: 46277.784 | B4: test.user@azar.com | C4: updateTask | D4: aa | E4: {"status":"Pending","score":""}
A5: 46277.785 | B5: test.user@azar.com | C5: updateTask | D5: aa | E5: {"status":"InProgress","score":""}
A6: 46277.785 | B6: test.user@azar.com | C6: updateTask | D6: aa | E6: {"status":"Completed","score":""}
A7: 46277.785 | B7: test.user@azar.com | C7: updateTask | D7: aa | E7: {"status":"Blocked","score":""}
A8: 46277.785 | B8: test.user@azar.com | C8: updateTask | D8: aa | E8: {"status":"Pending","score":""}
A9: 46277.785 | B9: test.user@azar.com | C9: updateTask | D9: aa | E9: {"status":"Pending","score":""}
A10: 46277.785 | B10: test.user@azar.com | C10: updateTask | D10: aa | E10: {"status":"Pending","score":""}
A11: 46277.786 | B11: test.user@azar.com | C11: updateTask | D11: aa | E11: {"status":"Pending","score":""}
A12: 46278.008 | B12: test.user@azar.com | C12: updateTask | D12: aa | E12: {"status":"InProgress","score":""}
A13: 46279.489 | B13: test.user@azar.com | C13: updateTask | D13: aa | E13: {"status":"Pending","score":""}
... A36: 46296.884 | B36: test.user@azar.com | C36: updateTask | D36: hard | E36: {"status":"Pending","score":""}

Sheet Team
A1: Name | B1: ID | C1: Mail | D1: Phone number | E1: Rule | F1: overview | G1: Hard Skill | H1: Soft Skill | I1: Technology | J1: Personality | K1: Abilities | L1: Education | M1: Role | N1: Reports To | O1: Department | P1: Aliases | Q1: Knowledge | R1: Skills | S1: Active
A2: Abdallah Refaat Allam | B2: 2520606 | C2: abdallahallam1550@gmail.com | D2: 1091157494 | F2: First-year IT student passionate about Robotics and Embedded Systems. Currently working on an autonomous robot using Arduino and ESP32, with hands-on experience in sensors, motor control, and communication systems. Eager to learn and gain practical experience in robotics. | G2: {Embedded Systems & Firmware (C/C++) , 2} {High-Level Scripting & Middleware (Python) , 1} {Version Control & Collaboration (Git/GitHub) , 2} {Embedded Linux & SBC Administration , 1} {Circuit Design & EDA Routing , 1} {Power Electronics & Circuit Protection , 1} {Mechanical Engineering & CAD , 2} {Kinematics & Motion Control , 1} {Sensor Fusion & State Estimation , 2} {Computer Vision & Spatial AI , 1} {SLM Fine tuning & Edge AI deployment , 1} | H2: {Systematic Root-Cause Isolatio , 1} {Critical Thinking & Architecture Trade-Off Analysis , 1} {Safety-First Engineering Mindset (Fail-Safe Design) , 1} {Adaptive Problem Solving & Agile Iteration , 1} {Cross-Domain Systems Integration , 1} | I2: {Autodesk Fusion 360 / SolidWorks , 1} {KiCad EDA (v7.0+) / Proetus , 1} {PlatformIO / VS Code / Arduino IDE 2.x , 2} {Raspberry Pi OS (64-bit) / Ubuntu Server , 1} {ROS 2 (Humble Hawksbill) , 1} {slam_toolbox & ROS 2 Nav2 , 1} {OpenCV & ONNX Runtime / TFLite , 1} {FastAPI (Python) / Express & WebSockets , 1} {Gazebo / RViz2 / WebSockets Injection , 1} | M2: Team Leader | P2: Abdallah Allm Abdallah-Allam Abdallah Refaat | S2: TRUE
A3: نور ياسر زكريا عزام | B3: 2521059 | C3: Nourazzam589@gmail.com | D3: 1277251600 | F3: نعم | G3: {Embedded Systems & Firmware (C/C++) , 1} {High-Level Scripting & Middleware (Python) , 1} {Version Control & Collaboration (Git/GitHub) , 1} {Embedded Linux & SBC Administration , 1} {Circuit Design & EDA Routing , 1} {Power Electronics & Circuit Protection , 1} {Mechanical Engineering & CAD , 1} {Kinematics & Motion Control , 1} {Sensor Fusion & State Estimation , 1} {Computer Vision & Spatial AI , 1} {SLM Fine tuning & Edge AI deployment , 1} | H3: {Systematic Root-Cause Isolatio , 1} {Critical Thinking & Architecture Trade-Off Analysis , 1} {Safety-First Engineering Mindset (Fail-Safe Design) , 1} {Adaptive Problem Solving & Agile Iteration , 1} {Cross-Domain Systems Integration , 1} | I3: {Autodesk Fusion 360 / SolidWorks , 1} {KiCad EDA (v7.0+) / Proetus , 1} {PlatformIO / VS Code / Arduino IDE 2.x , 1} {Raspberry Pi OS (64-bit) / Ubuntu Server , 1} {ROS 2 (Humble Hawksbill) , 1} {slam_toolbox & ROS 2 Nav2 , 1} {OpenCV & ONNX Runtime / TFLite , 1} {FastAPI (Python) / Express & WebSockets , 1} {Gazebo / RViz2 / WebSockets Injection , 1} | M3: Team member | N3: 2520594 | O3: Electronics & Embedded | S3: TRUE
A4: Mohamed hamada shabaan | B4: 2520780 | C4: mojo52830@gmail.com | D4: 1025844001 | F4: A passion for embedded systems and learning, and contributing as much as I can ASAR Tim, I have a modest experience in programming languages and operating robotics, and I'm always trying to move forward, and I hope to introduce Tim's active. | G4: {Embedded Systems & Firmware (C/C++) , 2} {High-Level Scripting & Middleware (Python) , 2} {Version Control & Collaboration (Git/GitHub) , 3} {Embedded Linux & SBC Administration , 1} {Circuit Design & EDA Routing , 2} {Power Electronics & Circuit Protection , 2} {Mechanical Engineering & CAD , 1} {Kinematics & Motion Control , 3} {Sensor Fusion & State Estimation , 2} {Computer Vision & Spatial AI , 2} {SLM Fine tuning & Edge AI deployment , 1} | H4: {Systematic Root-Cause Isolatio , 1} {Critical Thinking & Architecture Trade-Off Analysis , 2} {Safety-First Engineering Mindset (Fail-Safe Design) , 2} {Adaptive Problem Solving & Agile Iteration , 2} {Cross-Domain Systems Integration , 2} | I4: {Autodesk Fusion 360 / SolidWorks , 1} {KiCad EDA (v7.0+) / Proetus , 1} {PlatformIO / VS Code / Arduino IDE 2.x , 3} {Raspberry Pi OS (64-bit) / Ubuntu Server , 1} {ROS 2 (Humble Hawksbill) , 2} {slam_toolbox & ROS 2 Nav2 , 2} {OpenCV & ONNX Runtime / TFLite , 1} {FastAPI (Python) / Express & WebSockets , 2} {Gazebo / RViz2 / WebSockets Injection , 1} | M4: Leader | N4: 2520606 | O4: Software & AI | S4: TRUE
A5: Amany Bilal Abo zaid Deffalla | B5: 2520186 | C5: amanybilal36@gmail.com | D5: 1208185428 | G5: {Embedded Systems & Firmware (C/C++) , 3} {High-Level Scripting & Middleware (Python) , 3} {Version Control & Collaboration (Git/GitHub) , 2} {Embedded Linux & SBC Administration , 1} {Circuit Design & EDA Routing , 1} {Power Electronics & Circuit Protection , 1} {Mechanical Engineering & CAD , 1} {Kinematics & Motion Control , 2} {Sensor Fusion & State Estimation , 2} {Computer Vision & Spatial AI , 2} {SLM Fine tuning & Edge AI deployment , 1} | H5: {Systematic Root-Cause Isolatio , 1} {Critical Thinking & Architecture Trade-Off Analysis , 1} {Safety-First Engineering Mindset (Fail-Safe Design) , 1} {Adaptive Problem Solving & Agile Iteration , 2} {Cross-Domain Systems Integration , 1} | I5: {Autodesk Fusion 360 / SolidWorks , 1} {KiCad EDA (v7.0+) / Proetus , 1} {PlatformIO / VS Code / Arduino IDE 2.x , 3} {Raspberry Pi OS (64-bit) / Ubuntu Server , 1} {ROS 2 (Humble Hawksbill) , 1} {slam_toolbox & ROS 2 Nav2 , 1} {OpenCV & ONNX Runtime / TFLite , 1} {FastAPI (Python) / Express & WebSockets , 2} {Gazebo / RViz2 / WebSockets Injection , 1} | M5: Team member | N5: 2520780 | O5: Software & AI | S5: TRUE
A6: Abdelrhman Mohamed Abdelfttah Soliman | B6: 2520594 | C6: abdelrhmanalnagar18@gmail.com | D6: 1025031789 | G6: {Embedded Systems & Firmware (C/C++) , 1} {High-Level Scripting & Middleware (Python) , 1} {Version Control & Collaboration (Git/GitHub) , 1} {Embedded Linux & SBC Administration , 1} {Circuit Design & EDA Routing , 1} {Power Electronics & Circuit Protection , 1} {Mechanical Engineering & CAD , 1} {Kinematics & Motion Control , 1} {Sensor Fusion & State Estimation , 1} {Computer Vision & Spatial AI , 1} {SLM Fine tuning & Edge AI deployment , 1} | H6: {Systematic Root-Cause Isolatio , 1} {Critical Thinking & Architecture Trade-Off Analysis , 1} {Safety-First Engineering Mindset (Fail-Safe Design) , 1} {Adaptive Problem Solving & Agile Iteration , 1} {Cross-Domain Systems Integration , 1} | I6: {Autodesk Fusion 360 / SolidWorks , 1} {KiCad EDA (v7.0+) / Proetus , 1} {PlatformIO / VS Code / Arduino IDE 2.x , 1} {Raspberry Pi OS (64-bit) / Ubuntu Server , 1} {ROS 2 (Humble Hawksbill) , 1} {slam_toolbox & ROS 2 Nav2 , 1} {OpenCV & ONNX Runtime / TFLite , 1} {FastAPI (Python) / Express & WebSockets , 1} {Gazebo / RViz2 / WebSockets Injection , 1} | M6: Leader | N6: 2520606 | O6: Electronics & Embedded | S6: TRUE
A7: Ezzat Abdel Rafea Ahmed | B7: 2520622 | C7: ztbdalraf82@gmail.com | D7: 1226286900 | F7: تخصص تكنولوجيا ومعلومات وشبكات لدي شغف عمل في انظمه كاميرات ip cctv اسعي لتطوير والوصول العمل في شركه Cisco | G7: {Embedded Systems & Firmware (C/C++) , 1} {High-Level Scripting & Middleware (Python) , 2} {Version Control & Collaboration (Git/GitHub) , 1} {Embedded Linux & SBC Administration , 1} {Circuit Design & EDA Routing , 1} {Power Electronics & Circuit Protection , 1} {Mechanical Engineering & CAD , 1} {Kinematics & Motion Control , 1} {Sensor Fusion & State Estimation , 1} {Computer Vision & Spatial AI , 1} {SLM Fine tuning & Edge AI deployment , 1} | H7: {Systematic Root-Cause Isolatio , 1} {Critical Thinking & Architecture Trade-Off Analysis , 1} {Safety-First Engineering Mindset (Fail-Safe Design) , 1} {Adaptive Problem Solving & Agile Iteration , 1} {Cross-Domain Systems Integration , 1} | I7: {Autodesk Fusion 360 / SolidWorks , 1} {KiCad EDA (v7.0+) / Proetus , 1} {PlatformIO / VS Code / Arduino IDE 2.x , 1} {Raspberry Pi OS (64-bit) / Ubuntu Server , 1} {ROS 2 (Humble Hawksbill) , 1} {slam_toolbox & ROS 2 Nav2 , 1} {OpenCV & ONNX Runtime / TFLite , 1} {FastAPI (Python) / Express & WebSockets , 1} {Gazebo / RViz2 / WebSockets Injection , 1} | M7: Team member | N7: 2540213 | O7: Mechanics & Integration | S7: TRUE
A8: Mohamed farhat nasr ali | B8: 2540213 | C8: mohamedfarahat555566@gmail.com | D8: 1095844217 | F8: Motivated Information Technology student with a strong interest in programming and software development. Currently developing my skills in C, C++, Python, and computer networks. Eager to learn new technologies, gain practical experience, and contribute to real-world projects. | G8: {Embedded Systems & Firmware (C/C++) , 2} {High-Level Scripting & Middleware (Python) , 2} {Version Control & Collaboration (Git/GitHub) , 2} {Embedded Linux & SBC Administration , 2} {Circuit Design & EDA Routing , 2} {Power Electronics & Circuit Protection , 2} {Mechanical Engineering & CAD , 2} {Kinematics & Motion Control , 2} {Sensor Fusion & State Estimation , 2} {Computer Vision & Spatial AI , 2} {SLM Fine tuning & Edge AI deployment , 2} | H8: {Systematic Root-Cause Isolatio , 2} {Critical Thinking & Architecture Trade-Off Analysis , 2} {Safety-First Engineering Mindset (Fail-Safe Design) , 2} {Adaptive Problem Solving & Agile Iteration , 2} {Cross-Domain Systems Integration , 2} | I8: {Autodesk Fusion 360 / SolidWorks , 2} {KiCad EDA (v7.0+) / Proetus , 2} {PlatformIO / VS Code / Arduino IDE 2.x , 2} {Raspberry Pi OS (64-bit) / Ubuntu Server , 2} {ROS 2 (Humble Hawksbill) , 2} {slam_toolbox & ROS 2 Nav2 , 2} {OpenCV & ONNX Runtime / TFLite , 2} {FastAPI (Python) / Express & WebSockets , 3} {Gazebo / RViz2 / WebSockets Injection , 2} | M8: Leader | N8: 2520606 | O8: Mechanics & Integration | S8: TRUE
A9: Amal Mohamed Youssef Mahmoud | B9: 2520189 | C9: amlmhmdywsf7@gmail.com | D9: 1277166793 | G9: {Embedded Systems & Firmware (C/C++) , 2} {High-Level Scripting & Middleware (Python) , 2} {Version Control & Collaboration (Git/GitHub) , 1} {Embedded Linux & SBC Administration , 1} {Circuit Design & EDA Routing , 2} {Power Electronics & Circuit Protection , 2} {Mechanical Engineering & CAD , 1} {Kinematics & Motion Control , 1} {Sensor Fusion & State Estimation , 2} {Computer Vision & Spatial AI , 1} {SLM Fine tuning & Edge AI deployment , 1} | H9: {Systematic Root-Cause Isolatio , 2} {Critical Thinking & Architecture Trade-Off Analysis , 1} {Safety-First Engineering Mindset (Fail-Safe Design) , 2} {Adaptive Problem Solving & Agile Iteration , 2} {Cross-Domain Systems Integration , 1} | I9: {Autodesk Fusion 360 / SolidWorks , 1} {KiCad EDA (v7.0+) / Proetus , 1} {PlatformIO / VS Code / Arduino IDE 2.x , 1} {Raspberry Pi OS (64-bit) / Ubuntu Server , 1} {ROS 2 (Humble Hawksbill) , 1} {slam_toolbox & ROS 2 Nav2 , 1} {OpenCV & ONNX Runtime / TFLite , 1} {FastAPI (Python) / Express & WebSockets , 1} {Gazebo / RViz2 / WebSockets Injection , 1} | M9: Team member | N9: 2520594 | O9: Electronics & Embedded | S9: TRUE
A10: Ziyadmohamed abd elrady | B10: 2520448 | C10: ziyadmohamed7689@gmail.com | D10: 1026484558 | F10: .. | G10: {Embedded Systems & Firmware (C/C++) , 1} {High-Level Scripting & Middleware (Python) , 2} {Version Control & Collaboration (Git/GitHub) , 1} {Embedded Linux & SBC Administration , 1} {Circuit Design & EDA Routing , 1} {Power Electronics & Circuit Protection , 1} {Mechanical Engineering & CAD , 1} {Kinematics & Motion Control , 1} {Sensor Fusion & State Estimation , 1} {Computer Vision & Spatial AI , 1} {SLM Fine tuning & Edge AI deployment , 1} | H10: {Systematic Root-Cause Isolatio , 2} {Critical Thinking & Architecture Trade-Off Analysis , 2} {Safety-First Engineering Mindset (Fail-Safe Design) , 3} {Adaptive Problem Solving & Agile Iteration , 2} {Cross-Domain Systems Integration , 3} | I10: {Autodesk Fusion 360 / SolidWorks , 1} {KiCad EDA (v7.0+) / Proetus , 1} {PlatformIO / VS Code / Arduino IDE 2.x , 2} {Raspberry Pi OS (64-bit) / Ubuntu Server , 3} {ROS 2 (Humble Hawksbill) , 1} {slam_toolbox & ROS 2 Nav2 , 1} {OpenCV & ONNX Runtime / TFLite , 1} {FastAPI (Python) / Express & WebSockets , 1} {Gazebo / RViz2 / WebSockets Injection , 1} | M10: Team member | N10: 2540213 | O10: Mechanics & Integration | S10: TRUE
A11: Fatma Magdy Issa Abdel Baqi | B11: 2560172 | C11: fm3192820@gmail.com | D11: 1067110418 | F11: A 2nd-year Information Technology student at Borg El-Arab Technological University with hands-on experience in AI development. In my 1st year, I served as the AI Specialist for a Smart University Assistant project, where I developed an intelligent conversational AI integrated with a Telegram bot, web platform, and dedicated hardware device. The system automated student-faculty communication, real-time schedule updates, and instant query answering. I am eager to join a dedicated team for our 2nd-year graduation project to apply my AI skills, collaborate on innovative solutions, and build impactful technology together. | G11: {Embedded Systems & Firmware (C/C++) , 2} {High-Level Scripting & Middleware (Python) , 2} {Version Control & Collaboration (Git/GitHub) , 1} {Embedded Linux & SBC Administration , 2} {Circuit Design & EDA Routing , 3} {Power Electronics & Circuit Protection , 2} {Mechanical Engineering & CAD , 1} {Kinematics & Motion Control , 1} {Sensor Fusion & State Estimation , 1} {Computer Vision & Spatial AI , 1} {SLM Fine tuning & Edge AI deployment , 2} | H11: {Systematic Root-Cause Isolatio , 2} {Critical Thinking & Architecture Trade-Off Analysis , 2} {Safety-First Engineering Mindset (Fail-Safe Design) , 2} {Adaptive Problem Solving & Agile Iteration , 3} {Cross-Domain Systems Integration , 3} | I11: {Autodesk Fusion 360 / SolidWorks , 1} {KiCad EDA (v7.0+) / Proetus , 2} {PlatformIO / VS Code / Arduino IDE 2.x , 2} {Raspberry Pi OS (64-bit) / Ubuntu Server , 2} {ROS 2 (Humble Hawksbill) , 1} {slam_toolbox & ROS 2 Nav2 , 1} {OpenCV & ONNX Runtime / TFLite , 2} {FastAPI (Python) / Express & WebSockets , 3} {Gazebo / RViz2 / WebSockets Injection , 1} | M11: Team member | N11: 2520780 | O11: Software & AI | S11: TRUE
A12: Ahmed Mohamed Abu El-Fadl Ramadan | B12: 2540004 | C12: ahmedcor90@gmail.com | D12: 1283920280 | F12: Electrical Installation graduate from technical secondary school with 95.3%, moved to IT with Excellent grade and got Very Good in my second IT semester. Built and improved a university guide chatbot using Groq API on my own, made a simple backend under time pressure, and picked the best local AI model via Ollama that fits Raspberry Pi as an offline backup. Currently learning C, Git/GitHub and Linux basics. Ready to contribute and grow through hands on work. | G12: {Embedded Systems & Firmware (C/C++) , 1} {High-Level Scripting & Middleware (Python) , 1} {Version Control & Collaboration (Git/GitHub) , 1} {Embedded Linux & SBC Administration , 1} {Circuit Design & EDA Routing , 1} {Power Electronics & Circuit Protection , 1} {Mechanical Engineering & CAD , 1} {Kinematics & Motion Control , 1} {Sensor Fusion & State Estimation , 1} {Computer Vision & Spatial AI , 1} {SLM Fine tuning & Edge AI deployment , 2} | H12: {Systematic Root-Cause Isolatio , 2} {Critical Thinking & Architecture Trade-Off Analysis , 2} {Safety-First Engineering Mindset (Fail-Safe Design) , 1} {Adaptive Problem Solving & Agile Iteration , 2} {Cross-Domain Systems Integration , 2} | I12: {Autodesk Fusion 360 / SolidWorks , 1} {KiCad EDA (v7.0+) / Proetus , 1} {PlatformIO / VS Code / Arduino IDE 2.x , 1} {Raspberry Pi OS (64-bit) / Ubuntu Server , 1} {ROS 2 (Humble Hawksbill) , 1} {slam_toolbox & ROS 2 Nav2 , 1} {OpenCV & ONNX Runtime / TFLite , 1} {FastAPI (Python) / Express & WebSockets , 2} {Gazebo / RViz2 / WebSockets Injection , 1} | M12: Team member | N12: 2520594 | O12: Electronics & Embedded | S12: TRUE
A13: Mostafa Ahmed Sayed Ali Abou baker | B13: 2540244 | C13: mostafaabuobaker999@gmail.com | D13: 1032495429 | G13: {Embedded Systems & Firmware (C/C++) , 3} {High-Level Scripting & Middleware (Python) , 3} {Version Control & Collaboration (Git/GitHub) , 3} {Embedded Linux & SBC Administration , 1} {Circuit Design & EDA Routing , 1} {Power Electronics & Circuit Protection , 3} {Mechanical Engineering & CAD , 3} {Kinematics & Motion Control , 1} {Sensor Fusion & State Estimation , 1} {Computer Vision & Spatial AI , 1} {SLM Fine tuning & Edge AI deployment , 1} | H13: {Systematic Root-Cause Isolatio , 1} {Critical Thinking & Architecture Trade-Off Analysis , 1} {Safety-First Engineering Mindset (Fail-Safe Design) , 1} {Adaptive Problem Solving & Agile Iteration , 1} {Cross-Domain Systems Integration , 1} | I13: {Autodesk Fusion 360 / SolidWorks , 1} {KiCad EDA (v7.0+) / Proetus , 1} {PlatformIO / VS Code / Arduino IDE 2.x , 1} {Raspberry Pi OS (64-bit) / Ubuntu Server , 1} {ROS 2 (Humble Hawksbill) , 1} {slam_toolbox & ROS 2 Nav2 , 1} {OpenCV & ONNX Runtime / TFLite , 1} {FastAPI (Python) / Express & WebSockets , 1} {Gazebo / RViz2 / WebSockets Injection , 1} | M13: Team member | N13: 2540213 | O13: Mechanics & Integration | S13: TRUE
A14: يوسف وجدي السيد احمد | B14: 2540300 | C14: wagdeyyoussef@gmail.com | D14: 1200795169 | F14: انا خبرتي محدوده بس الي بيتطلب مني بعمله ايا كان حتى لو هتعلمه عادي | G14: {Embedded Systems & Firmware (C/C++) , 2} {High-Level Scripting & Middleware (Python) , 2} {Version Control & Collaboration (Git/GitHub) , 1} {Embedded Linux & SBC Administration , 1} {Circuit Design & EDA Routing , 1} {Power Electronics & Circuit Protection , 2} {Mechanical Engineering & CAD , 2} {Kinematics & Motion Control , 1} {Sensor Fusion & State Estimation , 2} {Computer Vision & Spatial AI , 2} {SLM Fine tuning & Edge AI deployment , 1} | H14: {Systematic Root-Cause Isolatio , 1} {Critical Thinking & Architecture Trade-Off Analysis , 1} {Safety-First Engineering Mindset (Fail-Safe Design) , 1} {Adaptive Problem Solving & Agile Iteration , 1} {Cross-Domain Systems Integration , 1} | I14: {Autodesk Fusion 360 / SolidWorks , 1} {KiCad EDA (v7.0+) / Proetus , 1} {PlatformIO / VS Code / Arduino IDE 2.x , 1} {Raspberry Pi OS (64-bit) / Ubuntu Server , 1} {ROS 2 (Humble Hawksbill) , 1} {slam_toolbox & ROS 2 Nav2 , 1} {OpenCV & ONNX Runtime / TFLite , 1} {FastAPI (Python) / Express & WebSockets , 1} {Gazebo / RViz2 / WebSockets Injection , 1} | M14: Team member | N14: 2520780 | O14: Software & AI | S14: TRUE
A15: Shams Mohammed Abd-ELhakim Galal | B15: 2560129 | C15: shamsgalal69@gmail.com | D15: 1508195848 | F15: I'm a student in the Department of Information Technology, and I am interested in programming, embedded systems, and robotics. I have experience with Arduino, ESP32, and Proteus, and a basic understanding of C/C++, Python, HTML, and JavaScript. I also have a foundational knowledge of networking and cybersecurity. I am eager to learn new technologies, develop my technical skills, and work as part of a team. | G15: {Embedded Systems & Firmware (C/C++) , 4} {High-Level Scripting & Middleware (Python) , 4} {Version Control & Collaboration (Git/GitHub) , 3} {Embedded Linux & SBC Administration , 3} {Circuit Design & EDA Routing , 3} {Power Electronics & Circuit Protection , 4} {Mechanical Engineering & CAD , 3} {Kinematics & Motion Control , 3} {Sensor Fusion & State Estimation , 3} {Computer Vision & Spatial AI , 4} {SLM Fine tuning & Edge AI deployment , 3} | H15: {Systematic Root-Cause Isolatio , 4} {Critical Thinking & Architecture Trade-Off Analysis , 4} {Safety-First Engineering Mindset (Fail-Safe Design) , 3} {Adaptive Problem Solving & Agile Iteration , 4} {Cross-Domain Systems Integration , 3} | I15: {Autodesk Fusion 360 / SolidWorks , 4} {KiCad EDA (v7.0+) / Proetus , 3} {PlatformIO / VS Code / Arduino IDE 2.x , 4} {Raspberry Pi OS (64-bit) / Ubuntu Server , 3} {ROS 2 (Humble Hawksbill) , 3} {slam_toolbox & ROS 2 Nav2 , 2} {OpenCV & ONNX Runtime / TFLite , 3} {FastAPI (Python) / Express & WebSockets , 4} {Gazebo / RViz2 / WebSockets Injection , 2} | M15: Team member | N15: 2520594 | O15: Electronics & Embedded | S15: TRUE
A16: Mohamed Elhot | B16: 2520756 | C16: mohamed_elhot13@gmail.com | D16: 1282073791 | G16: {Embedded Systems & Firmware (C/C++) , 1} {High-Level Scripting & Middleware (Python) , 1} {Version Control & Collaboration (Git/GitHub) , 1} {Embedded Linux & SBC Administration , 1} {Circuit Design & EDA Routing , 1} {Power Electronics & Circuit Protection , 1} {Mechanical Engineering & CAD , 1} {Kinematics & Motion Control , 1} {Sensor Fusion & State Estimation , 1} {Computer Vision & Spatial AI , 1} {SLM Fine tuning & Edge AI deployment , 1} | H16: {Systematic Root-Cause Isolatio , 1} {Critical Thinking & Architecture Trade-Off Analysis , 1} {Safety-First Engineering Mindset (Fail-Safe Design) , 1} {Adaptive Problem Solving & Agile Iteration , 1} {Cross-Domain Systems Integration , 1} | I16: {Autodesk Fusion 360 / SolidWorks , 1} {KiCad EDA (v7.0+) / Proetus , 1} {PlatformIO / VS Code / Arduino IDE 2.x , 1} {Raspberry Pi OS (64-bit) / Ubuntu Server , 1} {ROS 2 (Humble Hawksbill) , 1} {slam_toolbox & ROS 2 Nav2 , 1} {OpenCV & ONNX Runtime / TFLite , 1} {FastAPI (Python) / Express & WebSockets , 1} {Gazebo / RViz2 / WebSockets Injection , 1} | M16: Team member | N16: 2540213 | O16: Mechanics & Integration | S16: TRUE
A17: Shams Mohamed Gaber Eldeeb | B17: 2521242 | C17: shamseldeeb946@gmail.com | D17: 1021639139 | F17: I am a motivated IT student with a strong interest in robotics and embedded systems. I have previous experience working on ASAR's project, where I was involved in the hardware team. This experience helped me develop my teamwork, problem-solving, and practical engineering skills. I am eager to continue learning, improve my technical abilities, and contribute to ASAR's robotics projects, especially in hardware integration and control systems. | G17: {Embedded Systems & Firmware (C/C++) , 1} {High-Level Scripting & Middleware (Python) , 2} {Version Control & Collaboration (Git/GitHub) , 1} {Embedded Linux & SBC Administration , 1} {Circuit Design & EDA Routing , 1} {Power Electronics & Circuit Protection , 1} {Mechanical Engineering & CAD , 1} {Kinematics & Motion Control , 1} {Sensor Fusion & State Estimation , 1} {Computer Vision & Spatial AI , 1} {SLM Fine tuning & Edge AI deployment , 1} | H17: {Systematic Root-Cause Isolatio , 2} {Critical Thinking & Architecture Trade-Off Analysis , 2} {Safety-First Engineering Mindset (Fail-Safe Design) , 2} {Adaptive Problem Solving & Agile Iteration , 2} {Cross-Domain Systems Integration , 1} | I17: {Autodesk Fusion 360 / SolidWorks , 1} {KiCad EDA (v7.0+) / Proetus , 1} {PlatformIO / VS Code / Arduino IDE 2.x , 1} {Raspberry Pi OS (64-bit) / Ubuntu Server , 1} {ROS 2 (Humble Hawksbill) , 1} {slam_toolbox & ROS 2 Nav2 , 1} {OpenCV & ONNX Runtime / TFLite , 1} {FastAPI (Python) / Express & WebSockets , 1} {Gazebo / RViz2 / WebSockets Injection , 1} | M17: Team member | N17: 2520780 | O17: Software & AI | S17: TRUE
A18: Omnia Ahmed Samir | B18: 2520190 | C18: Omniasamir775@gmail.com | D18: 1144001142 | G18: {Embedded Systems & Firmware (C/C++) , 3} {High-Level Scripting & Middleware (Python) , 3} {Version Control & Collaboration (Git/GitHub) , 1} {Embedded Linux & SBC Administration , 3} {Circuit Design & EDA Routing , 2} {Power Electronics & Circuit Protection , 2} {Mechanical Engineering & CAD , 3} {Kinematics & Motion Control , 1} {Sensor Fusion & State Estimation , 1} {Computer Vision & Spatial AI , 2} {SLM Fine tuning & Edge AI deployment , 1} | H18: {Systematic Root-Cause Isolatio , 3} {Critical Thinking & Architecture Trade-Off Analysis , 4} {Safety-First Engineering Mindset (Fail-Safe Design) , 3} {Adaptive Problem Solving & Agile Iteration , 4} {Cross-Domain Systems Integration , 3} | I18: {Autodesk Fusion 360 / SolidWorks , 2} {KiCad EDA (v7.0+) / Proetus , 2} {PlatformIO / VS Code / Arduino IDE 2.x , 3} {Raspberry Pi OS (64-bit) / Ubuntu Server , 1} {ROS 2 (Humble Hawksbill) , 1} {slam_toolbox & ROS 2 Nav2 , 1} {OpenCV & ONNX Runtime / TFLite , 1} {FastAPI (Python) / Express & WebSockets , 2} {Gazebo / RViz2 / WebSockets Injection , 1} | M18: Team member | N18: 2520594 | O18: Electronics & Embedded | S18: TRUE
A19: A’laa Mohamed Elhafny | B19: 2520175 | C19: lolamoham2000@gmail.com | D19: 1143116077 | G19: {Embedded Systems & Firmware (C/C++) , 2} {High-Level Scripting & Middleware (Python) , 2} {Version Control & Collaboration (Git/GitHub) , 2} {Embedded Linux & SBC Administration , 2} {Circuit Design & EDA Routing , 1} {Power Electronics & Circuit Protection , 1} {Mechanical Engineering & CAD , 1} {Kinematics & Motion Control , 1} {Sensor Fusion & State Estimation , 1} {Computer Vision & Spatial AI , 1} {SLM Fine tuning & Edge AI deployment , 1} | H19: {Systematic Root-Cause Isolatio , 1} {Critical Thinking & Architecture Trade-Off Analysis , 1} {Safety-First Engineering Mindset (Fail-Safe Design) , 1} {Adaptive Problem Solving & Agile Iteration , 1} {Cross-Domain Systems Integration , 1} | I19: {Autodesk Fusion 360 / SolidWorks , 1} {KiCad EDA (v7.0+) / Proetus , 1} {PlatformIO / VS Code / Arduino IDE 2.x , 1} {Raspberry Pi OS (64-bit) / Ubuntu Server , 2} {ROS 2 (Humble Hawksbill) , 1} {slam_toolbox & ROS 2 Nav2 , 1} {OpenCV & ONNX Runtime / TFLite , 1} {FastAPI (Python) / Express & WebSockets , 1} {Gazebo / RViz2 / WebSockets Injection , 1} | M19: Team member | N19: 2540213 | O19: Mechanics & Integration | S19: TRUE
A20: Asmaa Aahraf | B20: 2550031 | C20: asmaaashraf1292007@gmail.com | D20: 1061672541 | G20: {Embedded Systems & Firmware (C/C++) , 1} {High-Level Scripting & Middleware (Python) , 1} {Version Control & Collaboration (Git/GitHub) , 1} {Embedded Linux & SBC Administration , 1} {Circuit Design & EDA Routing , 1} {Power Electronics & Circuit Protection , 1} {Mechanical Engineering & CAD , 1} {Kinematics & Motion Control , 1} {Sensor Fusion & State Estimation , 1} {Computer Vision & Spatial AI , 1} {SLM Fine tuning & Edge AI deployment , 1} | H20: {Systematic Root-Cause Isolatio , 1} {Critical Thinking & Architecture Trade-Off Analysis , 1} {Safety-First Engineering Mindset (Fail-Safe Design) , 1} {Adaptive Problem Solving & Agile Iteration , 1} {Cross-Domain Systems Integration , 1} | I20: {Autodesk Fusion 360 / SolidWorks , 1} {KiCad EDA (v7.0+) / Proetus , 1} {PlatformIO / VS Code / Arduino IDE 2.x , 1} {Raspberry Pi OS (64-bit) / Ubuntu Server , 1} {ROS 2 (Humble Hawksbill) , 1} {slam_toolbox & ROS 2 Nav2 , 1} {OpenCV & ONNX Runtime / TFLite , 1} {FastAPI (Python) / Express & WebSockets , 1} {Gazebo / RViz2 / WebSockets Injection , 1} | M20: Team member | N20: 2520780 | O20: Software & AI | S20: TRUE
A21: assem waleed khamis saleh | B21: 2560148 | C21: assemwaleed321@gmail.com | D21: 1021881710 | F21: I am currently studing in information technology department I am a fullstack web developer I have been working on several large-scaled projects such as e-commerce websites | G21: {Embedded Systems & Firmware (C/C++) , 2} {High-Level Scripting & Middleware (Python) , 3} {Version Control & Collaboration (Git/GitHub) , 4} {Embedded Linux & SBC Administration , 1} {Circuit Design & EDA Routing , 1} {Power Electronics & Circuit Protection , 1} {Mechanical Engineering & CAD , 1} {Kinematics & Motion Control , 1} {Sensor Fusion & State Estimation , 2} {Computer Vision & Spatial AI , 1} {SLM Fine tuning & Edge AI deployment , 1} | H21: {Systematic Root-Cause Isolatio , 1} {Critical Thinking & Architecture Trade-Off Analysis , 1} {Safety-First Engineering Mindset (Fail-Safe Design) , 1} {Adaptive Problem Solving & Agile Iteration , 1} {Cross-Domain Systems Integration , 1} | I21: {Autodesk Fusion 360 / SolidWorks , 1} {KiCad EDA (v7.0+) / Proetus , 1} {PlatformIO / VS Code / Arduino IDE 2.x , 1} {Raspberry Pi OS (64-bit) / Ubuntu Server , 1} {ROS 2 (Humble Hawksbill) , 1} {slam_toolbox & ROS 2 Nav2 , 1} {OpenCV & ONNX Runtime / TFLite , 1} {FastAPI (Python) / Express & WebSockets , 2} {Gazebo / RViz2 / WebSockets Injection , 1} | M21: Team member | N21: 2520594 | O21: Electronics & Embedded | S21: TRUE
A22: Ibrahim farag abd elmawgoud | B22: 2520070 | C22: Iprahem30001@gmail.com | D22: 1228081024 | G22: {Embedded Systems & Firmware (C/C++) , 2} {High-Level Scripting & Middleware (Python) , 2} {Version Control & Collaboration (Git/GitHub) , 2} {Embedded Linux & SBC Administration , 2} {Circuit Design & EDA Routing , 2} {Power Electronics & Circuit Protection , 2} {Mechanical Engineering & CAD , 2} {Kinematics & Motion Control , 2} {Sensor Fusion & State Estimation , 2} {Computer Vision & Spatial AI , 2} {SLM Fine tuning & Edge AI deployment , 2} | H22: {Systematic Root-Cause Isolatio , 2} {Critical Thinking & Architecture Trade-Off Analysis , 2} {Safety-First Engineering Mindset (Fail-Safe Design) , 3} {Adaptive Problem Solving & Agile Iteration , 2} {Cross-Domain Systems Integration , 2} | I22: {Autodesk Fusion 360 / SolidWorks , 1} {KiCad EDA (v7.0+) / Proetus , 1} {PlatformIO / VS Code / Arduino IDE 2.x , 1} {Raspberry Pi OS (64-bit) / Ubuntu Server , 1} {ROS 2 (Humble Hawksbill) , 1} {slam_toolbox & ROS 2 Nav2 , 2} {OpenCV & ONNX Runtime / TFLite , 2} {FastAPI (Python) / Express & WebSockets , 2} {Gazebo / RViz2 / WebSockets Injection , 1} | M22: Team member | N22: 2540213 | O22: Mechanics & Integration | S22: TRUE
A23: Abdallah abass Mohamed gad | B23: 2520609 | C23: abdallahabass305@gmail.com | D23: 1015028240 | G23: {Embedded Systems & Firmware (C/C++) , 1} {High-Level Scripting & Middleware (Python) , 1} {Version Control & Collaboration (Git/GitHub) , 1} {Embedded Linux & SBC Administration , 1} {Circuit Design & EDA Routing , 2} {Power Electronics & Circuit Protection , 2} {Mechanical Engineering & CAD , 1} {Kinematics & Motion Control , 1} {Sensor Fusion & State Estimation , 1} {Computer Vision & Spatial AI , 1} {SLM Fine tuning & Edge AI deployment , 1} | H23: {Systematic Root-Cause Isolatio , 1} {Critical Thinking & Architecture Trade-Off Analysis , 1} {Safety-First Engineering Mindset (Fail-Safe Design) , 1} {Adaptive Problem Solving & Agile Iteration , 1} {Cross-Domain Systems Integration , 1} | I23: {Autodesk Fusion 360 / SolidWorks , 1} {KiCad EDA (v7.0+) / Proetus , 1} {PlatformIO / VS Code / Arduino IDE 2.x , 1} {Raspberry Pi OS (64-bit) / Ubuntu Server , 1} {ROS 2 (Humble Hawksbill) , 1} {slam_toolbox & ROS 2 Nav2 , 1} {OpenCV & ONNX Runtime / TFLite , 1} {FastAPI (Python) / Express & WebSockets , 1} {Gazebo / RViz2 / WebSockets Injection , 1} | M23: Team member | N23: 2520780 | O23: Software & AI | S23: TRUE
A24: Ruqayya Abd El Mawjood Hamed | B24: 2520406 | C24: ruqayyaabdelmawjwd@gmail.com | D24: 1145388901 | G24: {Embedded Systems & Firmware (C/C++) , 2} {High-Level Scripting & Middleware (Python) , 2} {Version Control & Collaboration (Git/GitHub) , 2} {Embedded Linux & SBC Administration , 1} {Circuit Design & EDA Routing , 2} {Power Electronics & Circuit Protection , 2} {Mechanical Engineering & CAD , 1} {Kinematics & Motion Control , 1} {Sensor Fusion & State Estimation , 1} {Computer Vision & Spatial AI , 2} {SLM Fine tuning & Edge AI deployment , 1} | H24: {Systematic Root-Cause Isolatio , 1} {Critical Thinking & Architecture Trade-Off Analysis , 2} {Safety-First Engineering Mindset (Fail-Safe Design) , 1} {Adaptive Problem Solving & Agile Iteration , 2} {Cross-Domain Systems Integration , 2} | I24: {Autodesk Fusion 360 / SolidWorks , 1} {KiCad EDA (v7.0+) / Proetus , 1} {PlatformIO / VS Code / Arduino IDE 2.x , 1} {Raspberry Pi OS (64-bit) / Ubuntu Server , 2} {ROS 2 (Humble Hawksbill) , 1} {slam_toolbox & ROS 2 Nav2 , 1} {OpenCV & ONNX Runtime / TFLite , 1} {FastAPI (Python) / Express & WebSockets , 1} {Gazebo / RViz2 / WebSockets Injection , 1} | M24: Team member | N24: 2520594 | O24: Electronics & Embedded | S24: TRUE
A25: Ahmed Fathy ahmed laz | B25: 2520112 | C25: fathyumar3@gmail.com | D25: 1025601425 | G25: {Embedded Systems & Firmware (C/C++) , 1} {High-Level Scripting & Middleware (Python) , 1} {Version Control & Collaboration (Git/GitHub) , 1} {Embedded Linux & SBC Administration , 1} {Circuit Design & EDA Routing , 1} {Power Electronics & Circuit Protection , 1} {Mechanical Engineering & CAD , 1} {Kinematics & Motion Control , 1} {Sensor Fusion & State Estimation , 1} {Computer Vision & Spatial AI , 1} {SLM Fine tuning & Edge AI deployment , 1} | H25: {Systematic Root-Cause Isolatio , 1} {Critical Thinking & Architecture Trade-Off Analysis , 1} {Safety-First Engineering Mindset (Fail-Safe Design) , 1} {Adaptive Problem Solving & Agile Iteration , 1} {Cross-Domain Systems Integration , 1} | I25: {Autodesk Fusion 360 / SolidWorks , 1} {KiCad EDA (v7.0+) / Proetus , 1} {PlatformIO / VS Code / Arduino IDE 2.x , 1} {Raspberry Pi OS (64-bit) / Ubuntu Server , 1} {ROS 2 (Humble Hawksbill) , 1} {slam_toolbox & ROS 2 Nav2 , 1} {OpenCV & ONNX Runtime / TFLite , 1} {FastAPI (Python) / Express & WebSockets , 1} {Gazebo / RViz2 / WebSockets Injection , 1} | M25: Team member | N25: 2540213 | O25: Mechanics & Integration | S25: TRUE
A26: Rahma Fayez | B26: 2520398 | C26: rahmefayze76@gmail.com | D26: 1040769179 | G26: {Embedded Systems & Firmware (C/C++) , 1} {High-Level Scripting & Middleware (Python) , 2} {Version Control & Collaboration (Git/GitHub) , 1} {Embedded Linux & SBC Administration , 1} {Circuit Design & EDA Routing , 1} {Power Electronics & Circuit Protection , 2} {Mechanical Engineering & CAD , 1} {Kinematics & Motion Control , 1} {Sensor Fusion & State Estimation , 1} {Computer Vision & Spatial AI , 1} {SLM Fine tuning & Edge AI deployment , 1} | H26: {Systematic Root-Cause Isolatio , 1} {Critical Thinking & Architecture Trade-Off Analysis , 1} {Safety-First Engineering Mindset (Fail-Safe Design) , 1} {Adaptive Problem Solving & Agile Iteration , 1} {Cross-Domain Systems Integration , 1} | I26: {Autodesk Fusion 360 / SolidWorks , 1} {KiCad EDA (v7.0+) / Proetus , 1} {PlatformIO / VS Code / Arduino IDE 2.x , 1} {Raspberry Pi OS (64-bit) / Ubuntu Server , 1} {ROS 2 (Humble Hawksbill) , 1} {slam_toolbox & ROS 2 Nav2 , 1} {OpenCV & ONNX Runtime / TFLite , 1} {FastAPI (Python) / Express & WebSockets , 1} {Gazebo / RViz2 / WebSockets Injection , 1} | M26: Team member | N26: 2520780 | O26: Software & AI | S26: TRUE
A27: Ahlam Abdelbast Ebrhim | B27: 2560005 | C27: ahlamabdelbast525@gmail.com | D27: 1212337831 | G27: {Embedded Systems & Firmware (C/C++) , 2} {High-Level Scripting & Middleware (Python) , 3} {Version Control & Collaboration (Git/GitHub) , 1} {Embedded Linux & SBC Administration , 1} {Circuit Design & EDA Routing , 2} {Power Electronics & Circuit Protection , 3} {Mechanical Engineering & CAD , 2} {Kinematics & Motion Control , 1} {Sensor Fusion & State Estimation , 3} {Computer Vision & Spatial AI , 1} {SLM Fine tuning & Edge AI deployment , 1} | H27: {Systematic Root-Cause Isolatio , 2} {Critical Thinking & Architecture Trade-Off Analysis , 1} {Safety-First Engineering Mindset (Fail-Safe Design) , 2} {Adaptive Problem Solving & Agile Iteration , 1} {Cross-Domain Systems Integration , 3} | I27: {Autodesk Fusion 360 / SolidWorks , 3} {KiCad EDA (v7.0+) / Proetus , 2} {PlatformIO / VS Code / Arduino IDE 2.x , 3} {Raspberry Pi OS (64-bit) / Ubuntu Server , 2} {ROS 2 (Humble Hawksbill) , 1} {slam_toolbox & ROS 2 Nav2 , 2} {OpenCV & ONNX Runtime / TFLite , 2} {FastAPI (Python) / Express & WebSockets , 2} {Gazebo / RViz2 / WebSockets Injection , 3} | M27: Team member | N27: 2520594 | O27: Electronics & Embedded | S27: TRUE

Sheet SKILLs
A1: Hard Technical SKILLS | D1: Soft skills | F1: Technologies and Tools
A2: SKILL | B2: Technical Competency | C2: Specific Technical Application | D2: Skill | E2: Description | F2: Engineering Layer | G2: Software / Middleware Tool | H2: Function in Architecture
A3: Embedded Systems & Firmware (C/C++) | B3: Low-Level Hardware Drivers & Real-Time Loops | C3: Writing non-blocking C++ code, direct register manipulation, hardware timer interrupts, quadrature encoder decoding, and I2C/SPI/UART peripheral communication. | D3: Systematic Root-Cause Isolatio | E3: The ability to evaluate engineering compromises objectively—such as deciding whether to execute lightweight neural network inference locally on the Raspberry Pi for minimal latency versus invoking cloud APIs over WebSockets for higher model accuracy at the expense of network dependency. | F3: Mechanical CAD | G3: Autodesk Fusion 360 / SolidWorks | H3: 3D parametric chassis updates, component mounting layout, laser-cutting exports, and 3D printing STEP generation.
A4: High-Level Scripting & Middleware (Python) | B4: Computational Pipelines & ROS 2 Orchestration | C4: Rapid prototyping of vision scripts, ROS 2 node creation, asynchronous API management, and binding computer vision algorithms. | D4: Critical Thinking & Architecture Trade-Off Analysis | E4: Methodical troubleshooting across interconnected engineering layers. When a robot fails to navigate correctly, a engineer must systematically isolate whether the root cause is mechanical wheel slip, electromagnetic motor noise polluting sensor lines, ground loop voltage shifts, UART frame corruption, or a software deadlock in inter-thread communication. | F4: Electronic EDA | G4: KiCad EDA (v7.0+) | H4: Schematic capture, custom component footprints, PCB layout routing, Design Rule Checking (DRC), and Gerber file export.
A5: Version Control & Collaboration (Git/GitHub) | B5: Source Code Lifecycle Management | C5: Branch management, atomic commits, pull request workflows, conflict resolution, version tagging, and automated rollback recovery. | D5: Safety-First Engineering Mindset (Fail-Safe Design) | E5: Anticipating hardware and environmental failure modes before physical deployment. This includes designing latching and non-latching emergency-stop protocols, setting up automatic software timeouts for lost control signals, and enforcing battery under-voltage cutoffs. | F5: Embedded Firmware | G5: PlatformIO / VS Code / Arduino IDE 2.x | H5: Multi-target C/C++ compilation, board package management for ESP32 and AVR Mega, and static code analysis.
A6: Embedded Linux & SBC Administration | B6: System Commissioning & POSIX Operations | C6: Linux kernel configuration, GPIO access via libgpiod, multithreading, systemd service automation, and headless remote management. | D6: Adaptive Problem Solving & Agile Iteration | E6: Embracing an iterative "design-test-debug" approach when dealing with physical unexpected real-world variables, such as varying floor friction, ambient light interference on camera vision, and unexpected structural chassis vibrations. | F6: SBC Operating System | G6: Raspberry Pi OS (64-bit) / Ubuntu Server | H6: Headless Linux operating system, system service configuration, and hardware bus management (I2C, SPI, UART, CSI).
A7: Circuit Design & EDA Routing | B7: Schematic Capture & PCB Layout | C7: KiCad EDA schematic design, multi-layer board stackup, trace sizing for high-current motor paths, and ground plane separation. | D7: Cross-Domain Systems Integration | E7: Breaking down traditional engineering silos to integrate mechanical body design, electrical safety routing, low-level microcontrollers, and cloud/edge software into a unified functional system. | F7: Robotics Middleware | G7: ROS 2 (Humble Hawksbill) | H7: Node pub/sub messaging, transform tree management (tf2), parameter management, and service orchestration.
A8: Power Electronics & Circuit Protection | B8: Power Conditioning & Safety Isolation | C8: Switching buck converter regulation (LM2596/MP2307), 3S Li-ion/LiPo BMS integration, optocoupler signal isolation, flyback diode protection, and TVS surge suppression. | F8: SLAM & Navigation | G8: slam_toolbox & ROS 2 Nav2 | H8: Occupancy grid generation from LiDAR range vectors, global A* pathfinding, and local TEB trajectory optimization.
A9: Mechanical Engineering & CAD | B9: Parametric Modeling & Enclosures | C9: 2D/3D CAD in SolidWorks or Autodesk Fusion 360, enclosure design for 3D printing or laser cutting, center-of-gravity optimization, and chassis structural updates. | F9: Computer Vision & AI | G9: OpenCV & ONNX Runtime / TFLite | H9: Frame capture pipelines, camera calibration, object detection, and local execution of quantized AI models.
A10: Kinematics & Motion Control | B10: Dynamic Kinematics Modeling | C10: Differential and 4-wheel Mecanum forward/inverse kinematics, PID loop tuning, and PWM duty-cycle mapping. | F10: Web & API Gateway | G10: FastAPI (Python) / Express & WebSockets | H10: Local and cloud RESTful JSON API endpoints, low-latency telemetry streaming, and web-based dashboard hosting.
A11: Sensor Fusion & State Estimation | B11: Mathematical Filtering | C11: Complementary filtering, Extended Kalman Filters (EKF), Unscented Kalman Filters (UKF), and covariance matrix calculation. | F11: Simulation & Debugging | G11: Gazebo / RViz2 / WebSockets Injection | H11: 3D physics simulation, spatial transform visualization, and manual WebSockets telemetry testing.
A12: Computer Vision & Spatial AI | B12: Visual Perception & API Control | C12: OpenCV video pipelines, camera calibration, local ONNX/TFLite model execution, and REST/WebSocket API integration.
A13: SLM Fine tuninig & Edge AI deployment | C13: Deploy and fine tune Small langauges models on microcontrollers

Sheet Learning
A1: Topic name | B1: Track ID | C1: Track Name | D1: Obligability | E1: Skill | F1: Platform | G1: Link | H1: Event ID | I1: Invited/Assigned | J1: Due to Date | K1: Description | L1: Archived | M1: Deleted
A2: Complete Git & GitHub Course from Zero to Professional | B2: 1 | C2: Git & DevOps Mastery | D2: Mandatory | E2: Branching, Commits, Pull Requests, Conflict Resolution, Rollback | F2: YouTube (Elzero Web School) | G2: https://www.youtube.com/watch?v=ACOiGZoqC8w | H2: learning-61cd4da535264aa9
A3: Learn Git & GitHub Version Control System for Software | B3: 1 | C3: Git & DevOps Mastery | D3: Mandatory | E3: Local Repositories, Staging, Revert, Commit History | F3: YouTube (CloudKode) | G3: https://www.youtube.com/watch?v=fDkR0TDR9dI | H3: learning-d728ae4de0374299
A4: Team Workflow and Software Life Cycle: Git Flow Workflows | B4: 1 | C4: Git & DevOps Mastery | D4: Optional | E4: Remote Repos, Merge Requests, Team Code Reviews | G4: https://www.youtube.com/watch?v=AkIpdnup6G4 | H4: learning-8fa70608505346e6
A5: Basics of C Programming for Microcontrollers | B5: 2 | C5: C & Embedded Systems | D5: Mandatory | E5: Pointers, Memory Allocation, Non-blocking millis() Loops | F5: MaharaTech | G5: https://maharatech.gov.eg/course/view.php?id=2247 | H5: learning-20731eab424048a3
A6: Device Driver Development and C Code Generation for Microcontrollers (Embedded C Drivers) | B6: 2 | C6: C & Embedded Systems | D6: Mandatory | E6: Hardware Registers, ISR Interrupts, Quadrature Encoders, PWM Loop Tuning | F6: Learn In Depth | G6: https://ad.learn-in-depth-store.com/course/embedded-system | H6: learning-bd48b5fdb0ca4cd1
A7: Software Interfacing for Microcontrollers via Protocols (I2C / SPI / UART) | B7: 2 | C7: C & Embedded Systems | D7: Mandatory | E7: Serial Peripheral Drivers, Timer Hardware Interfacing | F7: YouTube (Eng. Ashraf AlMadhoun) | G7: https://www.youtube.com/watch?v=AC2WuElEjgg | H7: learning-99710067932a4fe6
A8: Linux System Administration and Software Components for Raspberry Pi | B8: 3 | C8: Embedded Linux & SBC Administration | D8: Mandatory | E8: Headless SSH Setup, Systemd Service Automation, POSIX Threads | F8: YouTube (Eng. Ashraf AlMadhoun) | G8: https://www.youtube.com/watch?v=AC2WuElEjgg | H8: learning-e75a58efec7645ac
A9: Controlling SBC Inputs and Outputs using libgpiod and Python | B9: 3 | C9: Embedded Linux & SBC Administration | D9: Mandatory | E9: SBC GPIO Bus Control, Linux Hardware Kernel Drivers | F9: Learn In Depth | G9: https://ad.learn-in-depth-store.com/course/embedded-system | H9: learning-152b09f6e59241e3
A10: Building IoT Gateways & Networks Track | B10: 3 | C10: Embedded Linux & SBC Administration | D10: Optional | E10: Linux Networking, Data Telemetry Buffering, System Services | F10: MaharaTech | G10: https://maharatech.gov.eg/course/view.php?id=2145 | H10: learning-bd393d83c3144934
A11: PCB Design and Manufacturing using KiCad (In Lab) | B11: 4 | C11: Electronics & PCB Design | D11: Mandatory | E11: KiCad Schematic Capture, Footprint Design, Design Rule Checks (DRC) | F11: YouTube (Dr. Walid Issa) | G11: https://www.youtube.com/watch?v=tKy9v-bi25U | H11: learning-179013836b924ef7
A12: Multi-Layer PCB Routing | B12: 4 | C12: Electronics & PCB Design | D12: Mandatory | E12: High-Current Motor Traces, Ground Plane Separation, Gerber Export | F12: YouTube (Specialized Electronics) | G12: https://www.youtube.com/watch?v=tt9BgSrsqPg | H12: learning-5df13a6035f5448f
A13: Design of Protection Circuits, Power Supply, and Signal Isolation (Electro-Safety) | B13: 4 | C13: Electronics & PCB Design | D13: Mandatory | E13: Buck Regulators (LM2596), BMS 3S, Optocouplers, TVS Diodes | F13: YouTube | G13: https://www.youtube.com/watch?v=W0y5D223NJ4 | H13: learning-fbbeffdc594f42a9
A14: Parametric Mechanical Design using Autodesk Fusion 360 | B14: 5 | C14: Mechanical CAD & Structure | D14: Mandatory | E14: 3D Parametric Modeling, Mounting Brackets, (.STL) 3D Printing | F14: YouTube | G14: https://www.youtube.com/watch?v=RDiI3K4rias | H14: learning-278d6a978f1742e0
A15: Robot Chassis Design and Load Distribution from Scratch in SolidWorks | B15: 5 | C15: Mechanical CAD & Structure | D15: Mandatory | E15: Center of Gravity Optimization, Sheet Metal Laser Cutting (.DXF) | F15: YouTube | G15: https://www.youtube.com/watch?v=XE9PlUljcyc | H15: learning-e33d2a8284ab46af
A16: Chassis Assembly and Mechanical Interference Calculation (CAD Assemblies) | B16: 5 | C16: Mechanical CAD & Structure | D16: Optional | E16: Mechanical Assembly Interference Checks, Chassis Tolerances | F16: YouTube | G16: https://www.youtube.com/watch?v=ISf3moboQB0 | H16: learning-84ad5b6fd68e4e56
... A30: Fail-Safe Engineering Design and Emergency Systems Management | B30: 10 | C30: Engineering Practice & Soft Skills | D30: Mandatory | E30: Safety-First Mindset, Emergency Stop Protocols, Hardware Redundancy | F30: Edraak | G30: https://www.edraak.org/programs/specialization/project-management-1/ | H30: learning-6156197ebc96478a

Sheet Meet
A1: Meeting title | B1: Meeting Type | C1: Date | D1: Description | E1: Attachments | F1: Event ID | G1: Invited/Assigned | H1: Due to Date | I1: Archived | J1: Logging Enabled | K1: Deleted
A2: Project overview | B2: online | C2: 46233 | D2: overview about the project asfasf | F2: meet-cc33802661d4412a
A3: Roobt | B3: offline | C3: 46264 | D3: afsasfafs | F3: meet-be1fd4b61bfe41d1

Sheet Exam
A1: Exam name | B1: Date | C1: Category | D1: # Attendee | E1: Event ID | F1: Invited/Assigned | G1: Due to Date | H1: Description | I1: Archived
A2: C exam | B2: 46233 | C2: Software | E2: exam-2010fa4625ed4b38

Sheet Task
A1: Task Title | B1: Task description | C1: Break down (DOD) | D1: Assignees | E1: Status | F1: Score | G1: Feedback | H1: ETA | I1: ATA | J1: Scale | K1: Archived | L1: Event ID | M1: Due to Date | N1: Evidence Links | O1: Deleted
A2: aa | B2: aaaa | D2: Abdallah Refaat | E2: Backlog | J2: day | L2: task-5c73d54129a14534
A3: a | B3: aff | C3: af | D3: Mohamed hamada shabaan | E3: Completed | H3: 2 | J3: week | K3: TRUE | L3: task-ffaf31b0ac334d0e
A4: hard | B4: a | C4: ad | D4: Abdallah Refaat,نور ياسر زكريا عزام | E4: Blocked | H4: 1 | J4: week | K4: TRUE | L4: task-fa4ac6cda0d745cb

Sheet Log
A1: Event Type | B1: Event ID | C1: Event Name | D1: Invited/Assigned | E1: Attendees/Completed | F1: Due to Date | G1: Source ID | H1: Archived | I1: Deleted
A2: Skill | B2: 1 | C2: Python | D2: Abdallah-Allam Abdelrahman M. Abdel-Fattah Mohamed H. Shaban Youssef Hammam Masoud Youssef Wagdy El-Sayed Assem Walid Khamis Mohamed Farhat Nasr Mostafa Ahmed Sayed Ezzat A. Ahmed Mbrok Fares Ibrahim Mohamed Ibrahim Faraj Abdel-Mawgoud Ahmed Fathy Ahmed Nour Yasser Zakaria Amani Bilal Abu Zeid Shams Mohamed Abdel-Hakim Manar Moussa Saeed Malak Ahmed Mohamed Alaa Mohamed El-Hefny Samah Mahdy Salah Yasmin Samir Abdessalam Asmaa Ashraf Attia Shams Mohamed Jaber Shaymaa Emad Mohamed | E2: Youssef Hammam Masoud Youssef Wagdy El-Sayed Assem Walid Khamis Mohamed Farhat Nasr Mostafa Ahmed Sayed Ezzat A. Ahmed Mbrok Fares Ibrahim Mohamed Ibrahim Faraj Abdel-Mawgoud | F2: 46233 | H2: TRUE
A3: Meet | B3: 2 | C3: bbb | D3: Abdallah-Allam | E3: Abdallah-Allam | F3: 46233

Sheet Admins
A1: Email | B1: Name | C1: Enabled
A2: abdallahallam1550@gmail.com | B2: Abdallah Refaat Allam | C2: TRUE

Sheet SkillEvents
A1: Event Name | B1: Target Skill | C1: Description | D1: Date | E1: Event ID | F1: Invited/Assigned | G1: Due to Date | H1: Archived | I1: Skill Category

Sheet Completion
A1: Timestamp | B1: Event Type | C1: Event ID | D1: Event Name | E1: Member ID | F1: Name | G1: Email | H1: Evidence | I1: Score | J1: Submission ID | K1: Status | L1: Evidence File ID | M1: Evidence URL | N1: Evidence Filename | O1: Evidence MIME Type | P1: Evidence Size | Q1: Reviewer Email | R1: Reviewer Name | S1: Reviewed At | T1: Review Note | U1: Status Changed At | V1: Status Changed By
D2: =IFERROR(INDEX(Lookups!$L$2:$L$62,MATCH(C2,Lookups!$K$2:$K$62,0)),"") | F2: =IFERROR(INDEX(Lookups!$B$2:$B$27,MATCH(E2,Lookups!$A$2:$A$27,0)),"") | G2: =IFERROR(INDEX(Lookups!$C$2:$C$27,MATCH(E2,Lookups!$A$2:$A$27,0)),"")
D3: =IFERROR(INDEX(Lookups!$L$2:$L$62,MATCH(C3,Lookups!$K$2:$K$62,0)),"") | F3: =IFERROR(INDEX(Lookups!$B$2:$B$27,MATCH(E3,Lookups!$A$2:$A$27,0)),"") | G3: =IFERROR(INDEX(Lookups!$C$2:$C$27,MATCH(E3,Lookups!$A$2:$A$27,0)),"")
D4: =IFERROR(INDEX(Lookups!$L$2:$L$62,MATCH(C4,Lookups!$K$2:$K$62,0)),"") | F4: =IFERROR(INDEX(Lookups!$B$2:$B$27,MATCH(E4,Lookups!$A$2:$A$27,0)),"") | G4: =IFERROR(INDEX(Lookups!$C$2:$C$27,MATCH(E4,Lookups!$A$2:$A$27,0)),"")
D5: =IFERROR(INDEX(Lookups!$L$2:$L$62,MATCH(C5,Lookups!$K$2:$K$62,0)),"") | F5: =IFERROR(INDEX(Lookups!$B$2:$B$27,MATCH(E5,Lookups!$A$2:$A$27,0)),"") | G5: =IFERROR(INDEX(Lookups!$C$2:$C$27,MATCH(E5,Lookups!$A$2:$A$27,0)),"")
D6: =IFERROR(INDEX(Lookups!$L$2:$L$62,MATCH(C6,Lookups!$K$2:$K$62,0)),"") | F6: =IFERROR(INDEX(Lookups!$B$2:$B$27,MATCH(E6,Lookups!$A$2:$A$27,0)),"") | G6: =IFERROR(INDEX(Lookups!$C$2:$C$27,MATCH(E6,Lookups!$A$2:$A$27,0)),"")
D7: =IFERROR(INDEX(Lookups!$L$2:$L$62,MATCH(C7,Lookups!$K$2:$K$62,0)),"") | F7: =IFERROR(INDEX(Lookups!$B$2:$B$27,MATCH(E7,Lookups!$A$2:$A$27,0)),"") | G7: =IFERROR(INDEX(Lookups!$C$2:$C$27,MATCH(E7,Lookups!$A$2:$A$27,0)),"")
D8: =IFERROR(INDEX(Lookups!$L$2:$L$62,MATCH(C8,Lookups!$K$2:$K$62,0)),"") | F8: =IFERROR(INDEX(Lookups!$B$2:$B$27,MATCH(E8,Lookups!$A$2:$A$27,0)),"") | G8: =IFERROR(INDEX(Lookups!$C$2:$C$27,MATCH(E8,Lookups!$A$2:$A$27,0)),"")
D9: =IFERROR(INDEX(Lookups!$L$2:$L$62,MATCH(C9,Lookups!$K$2:$K$62,0)),"") | F9: =IFERROR(INDEX(Lookups!$B$2:$B$27,MATCH(E9,Lookups!$A$2:$A$27,0)),"") | G9: =IFERROR(INDEX(Lookups!$C$2:$C$27,MATCH(E9,Lookups!$A$2:$A$27,0)),"")
D10: =IFERROR(INDEX(Lookups!$L$2:$L$62,MATCH(C10,Lookups!$K$2:$K$62,0)),"") | F10: =IFERROR(INDEX(Lookups!$B$2:$B$27,MATCH(E10,Lookups!$A$2:$A$27,0)),"") | G10: =IFERROR(INDEX(Lookups!$C$2:$C$27,MATCH(E10,Lookups!$A$2:$A$27,0)),"")
D11: =IFERROR(INDEX(Lookups!$L$2:$L$62,MATCH(C11,Lookups!$K$2:$K$62,0)),"") | F11: =IFERROR(INDEX(Lookups!$B$2:$B$27,MATCH(E11,Lookups!$A$2:$A$27,0)),"") | G11: =IFERROR(INDEX(Lookups!$C$2:$C$27,MATCH(E11,Lookups!$A$2:$A$27,0)),"")
D12: =IFERROR(INDEX(Lookups!$L$2:$L$62,MATCH(C12,Lookups!$K$2:$K$62,0)),"") | F12: =IFERROR(INDEX(Lookups!$B$2:$B$27,MATCH(E12,Lookups!$A$2:$A$27,0)),"") | G12: =IFERROR(INDEX(Lookups!$C$2:$C$27,MATCH(E12,Lookups!$A$2:$A$27,0)),"")
D13: =IFERROR(INDEX(Lookups!$L$2:$L$62,MATCH(C13,Lookups!$K$2:$K$62,0)),"") | F13: =IFERROR(INDEX(Lookups!$B$2:$B$27,MATCH(E13,Lookups!$A$2:$A$27,0)),"") | G13: =IFERROR(INDEX(Lookups!$C$2:$C$27,MATCH(E13,Lookups!$A$2:$A$27,0)),"")
